Workbook

Sheet Sheet1
A1: Variable | B1: Status | C1: Proxy | D1: Indicator | E1: Comment | F1: Source
A2: Management Age | B2: Low | C2: Average age of the executive team (CEO, CFO, COO, board), from public bios or officer records | D2: [READINESS] A younger executive team tends to be less anchored to legacy habits and faster to adopt new practices, echoing the 'young generation ready to revolutionize the business model' pattern already used in VIENNA to flag succession-driven openness. | E2: Correlation, not causation: some young leaders are more conservative than their predecessors. Use jointly with 'New Generation of Management' rather than alone. | F2: LinkedIn executive profiles, company leadership page, Handelsregister officer records, press bios
A3: Management National diversity | B3: High | C3: Nationality mix of the executive team and board, from public bios/LinkedIn | D3: [READINESS] Executives with international backgrounds are more likely to have been exposed to open-innovation practices abroad and less anchored to purely domestic norms. | E3: Weak signal alone; most useful combined with the International Sales Volume and Years of International Activity rows. | F3: LinkedIn, company leadership page, press bios
A4: Management cultural diversity | B4: High | C4: Cultural/educational background mix of the executive team, inferred from bios and education history across countries | D4: [READINESS] A management team drawing on varied cultural reference points tends to score higher on openness to unfamiliar ideas, similar to nationality diversity. | E4: Overlaps heavily with Management National Diversity, treat as a secondary confirmation signal rather than an independent one to avoid double-counting in a composite score. | F4: LinkedIn, bios, education history
A5: Management gender diversity | B5: High | C5: % of women in the executive team and on the supervisory board | D5: [READINESS] More gender-balanced leadership teams are associated in the management literature with broader information search and less groupthink, a weak positive proxy for openness. | E5: Evidence in the literature is mixed with small effect sizes; weight lower than succession or education signals in any composite score. | F5: LinkedIn, company leadership page, Handelsregister officer listing
A6: Management level of education | B6: High | C6: Share of the executive team holding a university degree or higher (Master's / MBA / PhD) | D6: [READINESS] Higher formal education correlates with greater comfort engaging with a structured, metrics-driven pilot framework like GG's, and faster uptake of unfamiliar analytical tools. | E6: Confidence: medium. Education level is easy to source for executives but rarely disclosed for the wider workforce, so treat this specifically as a leadership-team variable. | F6: LinkedIn education history, university alumni announcements, press bios
A7: Management diversity of education | B7: High | C7: Range of academic disciplines represented across the executive team (engineering, business, law, sciences, etc.) | D7: [READINESS] Cross-disciplinary leadership is more likely to recognize an unfamiliar external idea as relevant rather than dismiss it as outside its frame of reference. | E7: Confidence: medium, and best read together with row 6 rather than as an independent signal. | F7: LinkedIn education history
A8: New Generation of management | B8: Recent | C8: Family surname appearance in management | D8: [BOTH] A recent generational handover is both a NEED signal (incoming leadership typically wants to establish its own track record and reposition the business) and a READINESS signal (a newly installed generation is usually the most open to revising the business model, matching the succession pattern already flagged in VIENNA). | E8: The strongest single trigger-event variable in this table. Pair with Management Age for confirmation; treat a handover under 2 years old as a priority outreach signal. | F8: Handelsregister officer change filings, press releases announcing new CEO/MD, company 'our story' page
A9: Turnover of management | B9: High | C9: Number of C-suite/MD changes in the past 3 years | D9: [NEED] Frequent leadership turnover often coincides with a company actively searching for a new strategic direction, a NEED signal, though it carries the execution risk already noted in the existing comment. | E9: Could be a liability: company needs to find its way, but might not have the time | F9: Handelsregister officer change filings, press releases
A10: External collaboration | B10: Happened before | C10: Documented past partnerships with startups, universities, accelerators, or corporate venturing programs | D10: [READINESS] Prior participation in any external collaboration is the strongest behavioral proof of readiness available: it is revealed preference, not stated intent, and directly de-risks GG's pitch since the company has already cleared its internal approval hurdle once before. | E10: Weight more heavily than any self-reported openness variable, since it reflects observed behavior rather than a survey response. | F10: Press releases, university/accelerator case studies, company 'partners' page, patent co-assignments
A11: Interdepartmental collaboration | B11: High | C11: Not directly observable pre-contact in most cases; approximated via org-chart flatness or job postings mentioning 'cross-functional teams' | D11: [READINESS] Low silo-ing correlates with faster internal alignment to actually launch and staff a time-boxed pilot without a lengthy internal negotiation. | E11: Genuinely hard to source externally; best captured through a short first-contact questionnaire during the Diagnosi/scoping call rather than desk research. | F11: First-contact questionnaire (primary data), job postings mentioning cross-functional work, org chart if published
A12: Verticality in the structure | B12: Low | C12: Number of management layers between CEO and frontline staff, or self-reported at first contact | D12: [READINESS] Flatter hierarchies shorten the pilot approval chain, directly reducing the 'commitment gap / long complex sale' risk already flagged for SKEPTIC-level companies in VIENNA. | E12: Same sourcing limitation as the row above; best confirmed at first contact rather than assumed from desk research. | F12: First-contact questionnaire, org chart if published, headcount as a rough proxy (smaller firms tend to be flatter)
... A75: Prior digital maturity self-assessment | B75: Completed, low to medium maturity (DREAMY levels 1 to 3) | C75: Whether the company has taken a structured digital maturity assessment (Test Your Industry 4.0 / DREAMY via a Digital Innovation Hub, or a comparable audit) and the level obtained. | D75: [READINESS] Having completed an assessment is a strong openness signal, because the company has already looked at its own gaps. A low to medium result in the relevant area is exactly the target profile of high openness with low or medium readiness. | E75: Very high value but low coverage: results are self reported, held by the Hubs, and usable only with consent, so treat it as a partnership or first-contact data point, not a desk research variable. Caveat: DREAMY benchmarks are per sector and built on the 250+ companies that applied, a likely self-selected sample, so a level is only comparable within its sector and may overstate the population. | F75: Digital Innovation Hub partnership or consent-based data sharing, testindustria4-0.com assessment (self reported), first-contact questionnaire

Sheet Scoring Schema
A1: Sheet1 row | B1: Variable | C1: Axis tag (from Sheet1) | D1: Axis | E1: Polarity | F1: Role | G1: Acquisition mode | H1: Redundancy group (proposed) | I1: Weight on NEED axis | J1: Weight on READINESS axis | K1: Origin
A2: =ROW(Sheet1!A2) -> 2 | B2: =Sheet1!A2 -> Management Age | C2: =MID(Sheet1!D2,2,FIND("]",Sheet1!D2)-2) -> READINESS | D2: =IF(ISNUMBER(FIND("CONTEXT",C2)),"CONTEXT",IF(ISNUMBER(FIND("BOTH",C2)),"BOTH",IF(ISNUMBER(FIND("READINESS",C2)),"READINESS","NEED"))) -> READINESS | E2: =IF(ISNUMBER(FIND("NEGATIVE",C2)),"Negative","Standard") -> Standard | F2: Scored | G2: Web or job board scrape | H2: MGMT_AGE_TENURE | K2: Original
A3: =ROW(Sheet1!A3) -> 3 | B3: =Sheet1!A3 -> Management National diversity | C3: =MID(Sheet1!D3,2,FIND("]",Sheet1!D3)-2) -> READINESS | D3: =IF(ISNUMBER(FIND("CONTEXT",C3)),"CONTEXT",IF(ISNUMBER(FIND("BOTH",C3)),"BOTH",IF(ISNUMBER(FIND("READINESS",C3)),"READINESS","NEED"))) -> READINESS | E3: =IF(ISNUMBER(FIND("NEGATIVE",C3)),"Negative","Standard") -> Standard | F3: Scored | G3: Web or job board scrape | H3: MGMT_DIVERSITY | K3: Original
A4: =ROW(Sheet1!A4) -> 4 | B4: =Sheet1!A4 -> Management cultural diversity | C4: =MID(Sheet1!D4,2,FIND("]",Sheet1!D4)-2) -> READINESS | D4: =IF(ISNUMBER(FIND("CONTEXT",C4)),"CONTEXT",IF(ISNUMBER(FIND("BOTH",C4)),"BOTH",IF(ISNUMBER(FIND("READINESS",C4)),"READINESS","NEED"))) -> READINESS | E4: =IF(ISNUMBER(FIND("NEGATIVE",C4)),"Negative","Standard") -> Standard | F4: Scored | G4: Web or job board scrape | H4: MGMT_DIVERSITY | K4: Original
A5: =ROW(Sheet1!A5) -> 5 | B5: =Sheet1!A5 -> Management gender diversity | C5: =MID(Sheet1!D5,2,FIND("]",Sheet1!D5)-2) -> READINESS | D5: =IF(ISNUMBER(FIND("CONTEXT",C5)),"CONTEXT",IF(ISNUMBER(FIND("BOTH",C5)),"BOTH",IF(ISNUMBER(FIND("READINESS",C5)),"READINESS","NEED"))) -> READINESS | E5: =IF(ISNUMBER(FIND("NEGATIVE",C5)),"Negative","Standard") -> Standard | F5: Scored | G5: Web or job board scrape | H5: MGMT_DIVERSITY | K5: Original
A6: =ROW(Sheet1!A6) -> 6 | B6: =Sheet1!A6 -> Management level of education | C6: =MID(Sheet1!D6,2,FIND("]",Sheet1!D6)-2) -> READINESS | D6: =IF(ISNUMBER(FIND("CONTEXT",C6)),"CONTEXT",IF(ISNUMBER(FIND("BOTH",C6)),"BOTH",IF(ISNUMBER(FIND("READINESS",C6)),"READINESS","NEED"))) -> READINESS | E6: =IF(ISNUMBER(FIND("NEGATIVE",C6)),"Negative","Standard") -> Standard | F6: Scored | G6: Web or job board scrape | K6: Original
A7: =ROW(Sheet1!A7) -> 7 | B7: =Sheet1!A7 -> Management diversity of education | C7: =MID(Sheet1!D7,2,FIND("]",Sheet1!D7)-2) -> READINESS | D7: =IF(ISNUMBER(FIND("CONTEXT",C7)),"CONTEXT",IF(ISNUMBER(FIND("BOTH",C7)),"BOTH",IF(ISNUMBER(FIND("READINESS",C7)),"READINESS","NEED"))) -> READINESS | E7: =IF(ISNUMBER(FIND("NEGATIVE",C7)),"Negative","Standard") -> Standard | F7: Scored | G7: Web or job board scrape | H7: MGMT_DIVERSITY | K7: Original
A8: =ROW(Sheet1!A8) -> 8 | B8: =Sheet1!A8 -> New Generation of management | C8: =MID(Sheet1!D8,2,FIND("]",Sheet1!D8)-2) -> BOTH | D8: =IF(ISNUMBER(FIND("CONTEXT",C8)),"CONTEXT",IF(ISNUMBER(FIND("BOTH",C8)),"BOTH",IF(ISNUMBER(FIND("READINESS",C8)),"READINESS","NEED"))) -> BOTH | E8: =IF(ISNUMBER(FIND("NEGATIVE",C8)),"Negative","Standard") -> Standard | F8: Scored | G8: Registry or filing | H8: MGMT_AGE_TENURE | K8: Original
A9: =ROW(Sheet1!A9) -> 9 | B9: =Sheet1!A9 -> Turnover of management | C9: =MID(Sheet1!D9,2,FIND("]",Sheet1!D9)-2) -> NEED | D9: =IF(ISNUMBER(FIND("CONTEXT",C9)),"CONTEXT",IF(ISNUMBER(FIND("BOTH",C9)),"BOTH",IF(ISNUMBER(FIND("READINESS",C9)),"READINESS","NEED"))) -> NEED | E9: =IF(ISNUMBER(FIND("NEGATIVE",C9)),"Negative","Standard") -> Standard | F9: Scored | G9: Registry or filing | K9: Original
A10: =ROW(Sheet1!A10) -> 10 | B10: =Sheet1!A10 -> External collaboration | C10: =MID(Sheet1!D10,2,FIND("]",Sheet1!D10)-2) -> READINESS | D10: =IF(ISNUMBER(FIND("CONTEXT",C10)),"CONTEXT",IF(ISNUMBER(FIND("BOTH",C10)),"BOTH",IF(ISNUMBER(FIND("READINESS",C10)),"READINESS","NEED"))) -> READINESS | E10: =IF(ISNUMBER(FIND("NEGATIVE",C10)),"Negative","Standard") -> Standard | F10: Scored | G10: Manual desk research | K10: Original
A11: =ROW(Sheet1!A11) -> 11 | B11: =Sheet1!A11 -> Interdepartmental collaboration | C11: =MID(Sheet1!D11,2,FIND("]",Sheet1!D11)-2) -> READINESS | D11: =IF(ISNUMBER(FIND("CONTEXT",C11)),"CONTEXT",IF(ISNUMBER(FIND("BOTH",C11)),"BOTH",IF(ISNUMBER(FIND("READINESS",C11)),"READINESS","NEED"))) -> READINESS | E11: =IF(ISNUMBER(FIND("NEGATIVE",C11)),"Negative","Standard") -> Standard | F11: Scored | G11: First contact only | K11: Original
A12: =ROW(Sheet1!A12) -> 12 | B12: =Sheet1!A12 -> Verticality in the structure | C12: =MID(Sheet1!D12,2,FIND("]",Sheet1!D12)-2) -> READINESS | D12: =IF(ISNUMBER(FIND("CONTEXT",C12)),"CONTEXT",IF(ISNUMBER(FIND("BOTH",C12)),"BOTH",IF(ISNUMBER(FIND("READINESS",C12)),"READINESS","NEED"))) -> READINESS | E12: =IF(ISNUMBER(FIND("NEGATIVE",C12)),"Negative","Standard") -> Standard | F12: Scored | G12: First contact only | K12: Original
A13: =ROW(Sheet1!A13) -> 13 | B13: =Sheet1!A13 -> Employee turnover | C13: =MID(Sheet1!D13,2,FIND("]",Sheet1!D13)-2) -> READINESS | D13: =IF(ISNUMBER(FIND("CONTEXT",C13)),"CONTEXT",IF(ISNUMBER(FIND("BOTH",C13)),"BOTH",IF(ISNUMBER(FIND("READINESS",C13)),"READINESS","NEED"))) -> READINESS | E13: =IF(ISNUMBER(FIND("NEGATIVE",C13)),"Negative","Standard") -> Standard | F13: Scored | G13: Web or job board scrape | K13: Original
A14: =ROW(Sheet1!A14) -> 14 | B14: =Sheet1!A14 -> Number of Employees | C14: =MID(Sheet1!D14,2,FIND("]",Sheet1!D14)-2) -> READINESS | D14: =IF(ISNUMBER(FIND("CONTEXT",C14)),"CONTEXT",IF(ISNUMBER(FIND("BOTH",C14)),"BOTH",IF(ISNUMBER(FIND("READINESS",C14)),"READINESS","NEED"))) -> READINESS | E14: =IF(ISNUMBER(FIND("NEGATIVE",C14)),"Negative","Standard") -> Standard | F14: Scored | G14: Registry or filing | K14: Original
A15: =ROW(Sheet1!A15) -> 15 | B15: =Sheet1!A15 -> Average Salary | C15: =MID(Sheet1!D15,2,FIND("]",Sheet1!D15)-2) -> READINESS | D15: =IF(ISNUMBER(FIND("CONTEXT",C15)),"CONTEXT",IF(ISNUMBER(FIND("BOTH",C15)),"BOTH",IF(ISNUMBER(FIND("READINESS",C15)),"READINESS","NEED"))) -> READINESS | E15: =IF(ISNUMBER(FIND("NEGATIVE",C15)),"Negative","Standard") -> Standard | F15: Scored | G15: Web or job board scrape | K15: Original
A16: =ROW(Sheet1!A16) -> 16 | B16: =Sheet1!A16 -> Skilled Labour | C16: =MID(Sheet1!D16,2,FIND("]",Sheet1!D16)-2) -> READINESS | D16: =IF(ISNUMBER(FIND("CONTEXT",C16)),"CONTEXT",IF(ISNUMBER(FIND("BOTH",C16)),"BOTH",IF(ISNUMBER(FIND("READINESS",C16)),"READINESS","NEED"))) -> READINESS | E16: =IF(ISNUMBER(FIND("NEGATIVE",C16)),"Negative","Standard") -> Standard | F16: Scored | G16: Web or job board scrape | K16: Original
A17: =ROW(Sheet1!A17) -> 17 | B17: =Sheet1!A17 -> Volume of online sales | C17: =MID(Sheet1!D17,2,FIND("]",Sheet1!D17)-2) -> NEED | D17: =IF(ISNUMBER(FIND("CONTEXT",C17)),"CONTEXT",IF(ISNUMBER(FIND("BOTH",C17)),"BOTH",IF(ISNUMBER(FIND("READINESS",C17)),"READINESS","NEED"))) -> NEED | E17: =IF(ISNUMBER(FIND("NEGATIVE",C17)),"Negative","Standard") -> Standard | F17: Scored | G17: Web or job board scrape | H17: DIGITAL_FOOTPRINT | K17: Original
A18: =ROW(Sheet1!A18) -> 18 | B18: =Sheet1!A18 -> Online market presence | C18: =MID(Sheet1!D18,2,FIND("]",Sheet1!D18)-2) -> NEED | D18: =IF(ISNUMBER(FIND("CONTEXT",C18)),"CONTEXT",IF(ISNUMBER(FIND("BOTH",C18)),"BOTH",IF(ISNUMBER(FIND("READINESS",C18)),"READINESS","NEED"))) -> NEED | E18: =IF(ISNUMBER(FIND("NEGATIVE",C18)),"Negative","Standard") -> Standard | F18: Scored | G18: Web or job board scrape | H18: DIGITAL_FOOTPRINT | K18: Original
A19: =ROW(Sheet1!A19) -> 19 | B19: =Sheet1!A19 -> Number of physical stores | C19: =MID(Sheet1!D19,2,FIND("]",Sheet1!D19)-2) -> NEED | D19: =IF(ISNUMBER(FIND("CONTEXT",C19)),"CONTEXT",IF(ISNUMBER(FIND("BOTH",C19)),"BOTH",IF(ISNUMBER(FIND("READINESS",C19)),"READINESS","NEED"))) -> NEED | E19: =IF(ISNUMBER(FIND("NEGATIVE",C19)),"Negative","Standard") -> Standard | F19: Scored | G19: Web or job board scrape | H19: STORE_NETWORK | K19: Original
A20: =ROW(Sheet1!A20) -> 20 | B20: =Sheet1!A20 -> Geographic distribution of stores | C20: =MID(Sheet1!D20,2,FIND("]",Sheet1!D20)-2) -> NEED | D20: =IF(ISNUMBER(FIND("CONTEXT",C20)),"CONTEXT",IF(ISNUMBER(FIND("BOTH",C20)),"BOTH",IF(ISNUMBER(FIND("READINESS",C20)),"READINESS","NEED"))) -> NEED | E20: =IF(ISNUMBER(FIND("NEGATIVE",C20)),"Negative","Standard") -> Standard | F20: Scored | G20: Registry or filing | H20: STORE_NETWORK | K20: Original
A21: =ROW(Sheet1!A21) -> 21 | B21: =Sheet1!A21 -> International Sales volume | C21: =MID(Sheet1!D21,2,FIND("]",Sheet1!D21)-2) -> NEED | D21: =IF(ISNUMBER(FIND("CONTEXT",C21)),"CONTEXT",IF(ISNUMBER(FIND("BOTH",C21)),"BOTH",IF(ISNUMBER(FIND("READINESS",C21)),"READINESS","NEED"))) -> NEED | E21: =IF(ISNUMBER(FIND("NEGATIVE",C21)),"Negative","Standard") -> Standard | F21: Scored | G21: Registry or filing | H21: INTERNATIONAL | K21: Original
A22: =ROW(Sheet1!A22) -> 22 | B22: =Sheet1!A22 -> Years of international activity | C22: =MID(Sheet1!D22,2,FIND("]",Sheet1!D22)-2) -> NEED | D22: =IF(ISNUMBER(FIND("CONTEXT",C22)),"CONTEXT",IF(ISNUMBER(FIND("BOTH",C22)),"BOTH",IF(ISNUMBER(FIND("READINESS",C22)),"READINESS","NEED"))) -> NEED | E22: =IF(ISNUMBER(FIND("NEGATIVE",C22)),"Negative","Standard") -> Standard | F22: Scored | G22: Manual desk research | H22: INTERNATIONAL | K22: Original
A23: =ROW(Sheet1!A23) -> 23 | B23: =Sheet1!A23 -> Product demand | C23: =MID(Sheet1!D23,2,FIND("]",Sheet1!D23)-2) -> READINESS | D23: =IF(ISNUMBER(FIND("CONTEXT",C23)),"CONTEXT",IF(ISNUMBER(FIND("BOTH",C23)),"BOTH",IF(ISNUMBER(FIND("READINESS",C23)),"READINESS","NEED"))) -> READINESS | E23: =IF(ISNUMBER(FIND("NEGATIVE",C23)),"Negative","Standard") -> Standard | F23: Scored | G23: Manual desk research | K23: Original
A24: =ROW(Sheet1!A24) -> 24 | B24: =Sheet1!A24 -> Product differentiation | C24: =MID(Sheet1!D24,2,FIND("]",Sheet1!D24)-2) -> NEED | D24: =IF(ISNUMBER(FIND("CONTEXT",C24)),"CONTEXT",IF(ISNUMBER(FIND("BOTH",C24)),"BOTH",IF(ISNUMBER(FIND("READINESS",C24)),"READINESS","NEED"))) -> NEED | E24: =IF(ISNUMBER(FIND("NEGATIVE",C24)),"Negative","Standard") -> Standard | F24: Scored | G24: Manual desk research | K24: Original
A25: =ROW(Sheet1!A25) -> 25 | B25: =Sheet1!A25 -> Product portfolio diversity | C25: =MID(Sheet1!D25,2,FIND("]",Sheet1!D25)-2) -> NEED | D25: =IF(ISNUMBER(FIND("CONTEXT",C25)),"CONTEXT",IF(ISNUMBER(FIND("BOTH",C25)),"BOTH",IF(ISNUMBER(FIND("READINESS",C25)),"READINESS","NEED"))) -> NEED | E25: =IF(ISNUMBER(FIND("NEGATIVE",C25)),"Negative","Standard") -> Standard | F25: Scored | G25: Web or job board scrape | K25: Original
A26: =ROW(Sheet1!A26) -> 26 | B26: =Sheet1!A26 -> Rarity of raw materials | C26: =MID(Sheet1!D26,2,FIND("]",Sheet1!D26)-2) -> NEED | D26: =IF(ISNUMBER(FIND("CONTEXT",C26)),"CONTEXT",IF(ISNUMBER(FIND("BOTH",C26)),"BOTH",IF(ISNUMBER(FIND("READINESS",C26)),"READINESS","NEED"))) -> NEED | E26: =IF(ISNUMBER(FIND("NEGATIVE",C26)),"Negative","Standard") -> Standard | F26: Scored | G26: Manual desk research | K26: Original
A27: =ROW(Sheet1!A27) -> 27 | B27: =Sheet1!A27 -> Cost of raw materials | C27: =MID(Sheet1!D27,2,FIND("]",Sheet1!D27)-2) -> NEED | D27: =IF(ISNUMBER(FIND("CONTEXT",C27)),"CONTEXT",IF(ISNUMBER(FIND("BOTH",C27)),"BOTH",IF(ISNUMBER(FIND("READINESS",C27)),"READINESS","NEED"))) -> NEED | E27: =IF(ISNUMBER(FIND("NEGATIVE",C27)),"Negative","Standard") -> Standard | F27: Scored | G27: Registry or filing | K27: Original
A28: =ROW(Sheet1!A28) -> 28 | B28: =Sheet1!A28 -> Innovativeness of product | C28: =MID(Sheet1!D28,2,FIND("]",Sheet1!D28)-2) -> NEED | D28: =IF(ISNUMBER(FIND("CONTEXT",C28)),"CONTEXT",IF(ISNUMBER(FIND("BOTH",C28)),"BOTH",IF(ISNUMBER(FIND("READINESS",C28)),"READINESS","NEED"))) -> NEED | E28: =IF(ISNUMBER(FIND("NEGATIVE",C28)),"Negative","Standard") -> Standard | F28: Scored | G28: Manual desk research | K28: Original
A29: =ROW(Sheet1!A29) -> 29 | B29: =Sheet1!A29 -> Quality of product | C29: =MID(Sheet1!D29,2,FIND("]",Sheet1!D29)-2) -> NEED | D29: =IF(ISNUMBER(FIND("CONTEXT",C29)),"CONTEXT",IF(ISNUMBER(FIND("BOTH",C29)),"BOTH",IF(ISNUMBER(FIND("READINESS",C29)),"READINESS","NEED"))) -> NEED | E29: =IF(ISNUMBER(FIND("NEGATIVE",C29)),"Negative","Standard") -> Standard | F29: Scored | G29: Web or job board scrape | H29: QUALITY | K29: Original
A30: =ROW(Sheet1!A30) -> 30 | B30: =Sheet1!A30 -> Type of product | C30: =MID(Sheet1!D30,2,FIND("]",Sheet1!D30)-2) -> CONTEXT | D30: =IF(ISNUMBER(FIND("CONTEXT",C30)),"CONTEXT",IF(ISNUMBER(FIND("BOTH",C30)),"BOTH",IF(ISNUMBER(FIND("READINESS",C30)),"READINESS","NEED"))) -> CONTEXT | E30: =IF(ISNUMBER(FIND("NEGATIVE",C30)),"Negative","Standard") -> Standard | F30: Moderator | G30: Web or job board scrape | K30: Original
A31: =ROW(Sheet1!A31) -> 31 | B31: =Sheet1!A31 -> Product age | C31: =MID(Sheet1!D31,2,FIND("]",Sheet1!D31)-2) -> NEED | D31: =IF(ISNUMBER(FIND("CONTEXT",C31)),"CONTEXT",IF(ISNUMBER(FIND("BOTH",C31)),"BOTH",IF(ISNUMBER(FIND("READINESS",C31)),"READINESS","NEED"))) -> NEED | E31: =IF(ISNUMBER(FIND("NEGATIVE",C31)),"Negative","Standard") -> Standard | F31: Scored | G31: Manual desk research | K31: Original
A32: =ROW(Sheet1!A32) -> 32 | B32: =Sheet1!A32 -> Difficulty of logistics | C32: =MID(Sheet1!D32,2,FIND("]",Sheet1!D32)-2) -> NEED | D32: =IF(ISNUMBER(FIND("CONTEXT",C32)),"CONTEXT",IF(ISNUMBER(FIND("BOTH",C32)),"BOTH",IF(ISNUMBER(FIND("READINESS",C32)),"READINESS","NEED"))) -> NEED | E32: =IF(ISNUMBER(FIND("NEGATIVE",C32)),"Negative","Standard") -> Standard | F32: Scored | G32: First contact only | K32: Original
A33: =ROW(Sheet1!A33) -> 33 | B33: =Sheet1!A33 -> EBIT | C33: =MID(Sheet1!D33,2,FIND("]",Sheet1!D33)-2) -> NEED | D33: =IF(ISNUMBER(FIND("CONTEXT",C33)),"CONTEXT",IF(ISNUMBER(FIND("BOTH",C33)),"BOTH",IF(ISNUMBER(FIND("READINESS",C33)),"READINESS","NEED"))) -> NEED | E33: =IF(ISNUMBER(FIND("NEGATIVE",C33)),"Negative","Standard") -> Standard | F33: Scored | G33: Registry or filing | H33: PROFITABILITY | K33: Original
A34: =ROW(Sheet1!A34) -> 34 | B34: =Sheet1!A34 -> Gross Margin | C34: =MID(Sheet1!D34,2,FIND("]",Sheet1!D34)-2) -> NEED | D34: =IF(ISNUMBER(FIND("CONTEXT",C34)),"CONTEXT",IF(ISNUMBER(FIND("BOTH",C34)),"BOTH",IF(ISNUMBER(FIND("READINESS",C34)),"READINESS","NEED"))) -> NEED | E34: =IF(ISNUMBER(FIND("NEGATIVE",C34)),"Negative","Standard") -> Standard | F34: Scored | G34: Registry or filing | H34: PROFITABILITY | K34: Original
A35: =ROW(Sheet1!A35) -> 35 | B35: =Sheet1!A35 -> Revenues | C35: =MID(Sheet1!D35,2,FIND("]",Sheet1!D35)-2) -> NEED | D35: =IF(ISNUMBER(FIND("CONTEXT",C35)),"CONTEXT",IF(ISNUMBER(FIND("BOTH",C35)),"BOTH",IF(ISNUMBER(FIND("READINESS",C35)),"READINESS","NEED"))) -> NEED | E35: =IF(ISNUMBER(FIND("NEGATIVE",C35)),"Negative","Standard") -> Standard | F35: Scored | G35: Registry or filing | H35: PROFITABILITY | K35: Original
A36: =ROW(Sheet1!A36) -> 36 | B36: =Sheet1!A36 -> Interest Coverage Ratio | C36: =MID(Sheet1!D36,2,FIND("]",Sheet1!D36)-2) -> NEED | D36: =IF(ISNUMBER(FIND("CONTEXT",C36)),"CONTEXT",IF(ISNUMBER(FIND("BOTH",C36)),"BOTH",IF(ISNUMBER(FIND("READINESS",C36)),"READINESS","NEED"))) -> NEED | E36: =IF(ISNUMBER(FIND("NEGATIVE",C36)),"Negative","Standard") -> Standard | F36: Scored | G36: Registry or filing | H36: LEVERAGE_LIQUIDITY | K36: Original
A37: =ROW(Sheet1!A37) -> 37 | B37: =Sheet1!A37 -> Materials Cost | C37: =MID(Sheet1!D37,2,FIND("]",Sheet1!D37)-2) -> NEED | D37: =IF(ISNUMBER(FIND("CONTEXT",C37)),"CONTEXT",IF(ISNUMBER(FIND("BOTH",C37)),"BOTH",IF(ISNUMBER(FIND("READINESS",C37)),"READINESS","NEED"))) -> NEED | E37: =IF(ISNUMBER(FIND("NEGATIVE",C37)),"Negative","Standard") -> Standard | F37: Scored | G37: Registry or filing | H37: COST_STRUCTURE | K37: Original
A38: =ROW(Sheet1!A38) -> 38 | B38: =Sheet1!A38 -> Labour Cost | C38: =MID(Sheet1!D38,2,FIND("]",Sheet1!D38)-2) -> NEED | D38: =IF(ISNUMBER(FIND("CONTEXT",C38)),"CONTEXT",IF(ISNUMBER(FIND("BOTH",C38)),"BOTH",IF(ISNUMBER(FIND("READINESS",C38)),"READINESS","NEED"))) -> NEED | E38: =IF(ISNUMBER(FIND("NEGATIVE",C38)),"Negative","Standard") -> Standard | F38: Scored | G38: Registry or filing | H38: COST_STRUCTURE | K38: Original
A39: =ROW(Sheet1!A39) -> 39 | B39: =Sheet1!A39 -> Logistics Costs | C39: =MID(Sheet1!D39,2,FIND("]",Sheet1!D39)-2) -> NEED | D39: =IF(ISNUMBER(FIND("CONTEXT",C39)),"CONTEXT",IF(ISNUMBER(FIND("BOTH",C39)),"BOTH",IF(ISNUMBER(FIND("READINESS",C39)),"READINESS","NEED"))) -> NEED | E39: =IF(ISNUMBER(FIND("NEGATIVE",C39)),"Negative","Standard") -> Standard | F39: Scored | G39: Registry or filing | H39: COST_STRUCTURE | K39: Original
A40: =ROW(Sheet1!A40) -> 40 | B40: =Sheet1!A40 -> Energy Costs | C40: =MID(Sheet1!D40,2,FIND("]",Sheet1!D40)-2) -> NEED | D40: =IF(ISNUMBER(FIND("CONTEXT",C40)),"CONTEXT",IF(ISNUMBER(FIND("BOTH",C40)),"BOTH",IF(ISNUMBER(FIND("READINESS",C40)),"READINESS","NEED"))) -> NEED | E40: =IF(ISNUMBER(FIND("NEGATIVE",C40)),"Negative","Standard") -> Standard | F40: Scored | G40: Registry or filing | H40: COST_STRUCTURE | K40: Original
...

Sheet Change Log
A1: # | B1: Sheet1 row | C1: Variable | D1: Action | E1: What changed | F1: Why (DREAMY link)
A2: 1 | B2: 63 | C2: =Sheet1!A63 -> ERP / core systems age | D2: Modified | E2: Status now measures age only; Indicator wording trimmed; Comment points to row 72. | F2: DREAMY separates system technology from system integration. One row was carrying both.
A3: 2 | B3: 72 | C3: =Sheet1!A72 -> System integration across core functions (ERP, MES, CMMS, PLM, quality, finance) | D3: Added | E3: System integration across core functions, tagged NEED with readiness caveat. | F3: Integration and interoperability is DREAMY level 4, with a Digital Backbone as a cross-cutting layer.
A4: 3 | B4: 73 | C4: =Sheet1!A73 -> Maintenance management digitization | D4: Added | E4: Maintenance management digitization, tagged NEED, N/A for non asset-heavy firms. | F4: Maintenance is one of DREAMY's five areas and was entirely missing from the list.
A5: 4 | B5: 74 | C5: =Sheet1!A74 -> Quality process maturity | D5: Added | E5: Quality process maturity, tagged BOTH, proxied by sector-relevant certifications. | F5: DREAMY scores Quality as a process area; row 29 only captures outcome via reviews, which B2B firms rarely have.
A6: 5 | B6: 75 | C6: =Sheet1!A75 -> Prior digital maturity self-assessment | D6: Added | E6: Prior digital maturity self-assessment, tagged READINESS, first-contact or Hub data. | F6: DREAMY assessments are a direct openness signal and a baseline level; sector benchmark caveat noted in the Comment.
A7: 6 | B7: 29 | C7: =Sheet1!A29 -> Quality of product | D7: Not changed | E7: Original text untouched. Row 74 complements it. | F7: See row 74.
A8: 7 | B8: 57, 68, 69, 70 | C8: Axis tags | D8: Modified | E8: Separator inside the tag changed from a spaced hyphen to a comma in rows added earlier. | F8: House style. Row 49 (original, user text) left as it was; the Scoring Schema reads both forms.
A9: 8 | B9: All other | C9: All other cells | D9: Not changed | E9: Rows 2 to 62, 64 to 71 and all user-written text are as before.
B12: Open items
B13: Source column is written mostly for German registries (Bundesanzeiger, Handelsregister, DPMA). The project now runs on Italy and AIDA, so an Italian source mapping per row is still to be added.
B14: Most sector benchmarks implied by DREAMY come from Italian Hub assessments of self-selecting companies. Treat them as a prior to test, not a norm.
B15: Weights are intentionally empty on the Scoring Schema sheet pending the weighting discussion.
B16: Landing Bay specific project variables (backlog, work in progress, collection days, margin erosion on commessa) are not yet in the list.
